<?xml version="1.0"?>
<robot xmlns:xacro="http://www.ros.org/wiki/xacro">

  <!--
    wheels.xacro defines:
    1. A reusable drive_wheel macro  — called twice for left and right
    2. The caster wheel link and joint

    WHY a macro for wheels?
    Left and right wheels are identical in shape, mass, and inertia.
    The only difference is their Y position (left = positive, right = negative)
    and their name. A macro lets us define the wheel once and instantiate
    it twice with different arguments. One change updates both wheels.
  -->

  <!-- Include shared files -->



  <!-- ═══════════════════════════════════════════
       WHEEL DIMENSIONS AND PLACEMENT
       ═══════════════════════════════════════════ -->

  <!--
    These properties define every physical aspect of the wheels.
    They are used inside the macro below via ${} expressions.
  -->

  <xacro:property name="wheel_radius"       value="0.05"/>   <!-- metres -->
  <xacro:property name="wheel_length"       value="0.04"/>   <!-- thickness of wheel -->
  <xacro:property name="wheel_mass"         value="0.3"/>    <!-- kg per wheel -->

  <!--
    wheel_separation: distance between left and right wheel centres (y axis).
    This MUST match the value in the Gazebo diff_drive plugin exactly.
    Our chassis is 0.30m wide. Wheels sit just outside: 0.30/2 + 0.04/2 = 0.17m
    So separation = 0.17 * 2 = 0.34m between centres.
    We define half-separation here: each wheel is 0.17m from robot centre.
  -->
  <xacro:property name="wheel_y_offset"     value="0.17"/>   <!-- half of separation -->

  <!--
    wheel_z_offset: how far below base_link origin the wheel centre sits.
    base_link origin is at the vertical centre of the chassis (height/2 + ground_clearance = 0.10m above ground).
    Wheel centre must be at wheel_radius (z=0.05m in world frame) to touch the ground.
    Since base_link is at z=0.10, wheel centre must be 0.05m below base_link origin.
    So wheel_z_offset = -0.05m.
  -->
  <xacro:property name="wheel_z_offset"     value="-0.05"/>

  <!--
    wheel_x_offset: how far back from the chassis centre the drive wheels are placed.
    We place them slightly behind the centre (e.g. -0.10m) so that the robot is more
    stable when carrying weight in the rear, preventing the front caster from lifting.
  -->
  <xacro:property name="wheel_x_offset"     value="-0.10"/>

  <!-- Caster wheel dimensions -->
  <xacro:property name="caster_radius"      value="0.025"/>  <!-- metres -->
  <xacro:property name="caster_mass"        value="0.1"/>    <!-- kg -->

  <!--
    caster_x_offset: how far forward the caster sits from robot centre.
    Place it near the front edge of the chassis: base_length/2 - small margin.
    base_length = 0.40m, so front edge is at x=0.20. Place caster at x=0.15.
  -->
  <xacro:property name="caster_x_offset"    value="0.15"/>

  <!--
    caster_z_offset: caster centre below base_link origin.
    Caster radius = 0.025m. It must touch the ground (z=0 in world frame).
    base_link is at z=0.10 in world. So caster centre must be at z=0.025 world.
    Offset from base_link = 0.025 - 0.10 = -0.075m.
  -->
  <xacro:property name="caster_z_offset"    value="-0.075"/>


  <!-- ═══════════════════════════════════════════
       DRIVE WHEEL MACRO
       ═══════════════════════════════════════════ -->

  <!--
    params:
      prefix   — "left" or "right" — used in link name and joint name
      y_reflect — 1 for left wheel, -1 for right wheel
                  multiplied by wheel_y_offset to flip the Y position

    How the cylinder orientation works:
      A URDF cylinder is defined standing upright — its length runs along Z.
      We want the wheel lying on its side — length runs along Y (axle direction).
      So we rotate the visual and collision 90 degrees around X axis.
      rpy="${PI/2} 0 0" = 90 degrees around X = cylinder now lies along Y.
      The joint axis xyz="0 1 0" tells Gazebo to spin around Y — the wheel rolls.
  -->
  <xacro:macro name="drive_wheel" params="prefix y_reflect">

    <link name="${prefix}_wheel">

      <visual>
        <geometry>
          <cylinder radius="${wheel_radius}" length="${wheel_length}"/>
        </geometry>
        <!--
          rpy="${PI/2} 0 0" rotates the cylinder 90deg around X.
          This makes the wheel stand upright (lying on its side like a real wheel).
          Without this rotation the cylinder would be a disc lying flat on the ground.
        -->
        <origin xyz="0 0 0" rpy="${PI/2} 0 0"/>
        <material name="dark_grey"/>
      </visual>

      <collision>
        <geometry>
          <cylinder radius="${wheel_radius}" length="${wheel_length}"/>
        </geometry>
        <origin xyz="0 0 0" rpy="${PI/2} 0 0"/>
      </collision>

      <!--
        cylinder_inertia macro from inertia_macros.xacro.
        m = wheel_mass, r = wheel_radius, l = wheel_length
        The macro computes ixx, iyy, izz automatically.
      -->
      <xacro:cylinder_inertia
        m="${wheel_mass}"
        r="${wheel_radius}"
        l="${wheel_length}"/>

    </link>

    <!--
      DRIVE WHEEL JOINT
      type="continuous" — rotates forever with no limits.
      This is correct for drive wheels. Never use "revolute" for wheels
      because revolute has hard angle stops — wheels would stop turning.

      origin xyz:
        x = wheel_x_offset — wheel is placed slightly behind the chassis centre for stability
        y = y_reflect * wheel_y_offset
            left wheel:  y_reflect= 1 → y= +0.17 (left side)
            right wheel: y_reflect=-1 → y= -0.17 (right side)
        z = wheel_z_offset = -0.05 (below base_link at ground level)

      axis xyz="0 1 0" — wheel spins around Y axis.
      Combined with the rpy rotation of the visual, this is correct.
    -->
    <joint name="${prefix}_wheel_joint" type="continuous">
      <parent link="base_link"/>
      <child  link="${prefix}_wheel"/>
      <origin xyz="${wheel_x_offset} ${y_reflect * wheel_y_offset} ${wheel_z_offset}"
              rpy="0 0 0"/>
      <axis xyz="0 1 0"/>
      <!--
        dynamics: damping resists motion (simulates bearing friction).
        friction: static friction at the joint (separate from surface friction).
        These small values make simulation more stable and realistic.
      -->
      <dynamics damping="0.005" friction="0.05"/>
    </joint>

  </xacro:macro>


  <!-- ═══════════════════════════════════════════
       INSTANTIATE DRIVE WHEELS
       Call the macro twice — one line each.
       ═══════════════════════════════════════════ -->

  <!--
    left wheel:  prefix="left"  y_reflect= 1 → joint at y=+0.17
    right wheel: prefix="right" y_reflect=-1 → joint at y=-0.17
  -->
  <xacro:drive_wheel prefix="left"  y_reflect="1"/>
  <xacro:drive_wheel prefix="right" y_reflect="-1"/>


  <!-- ═══════════════════════════════════════════
       CASTER WHEEL
       ═══════════════════════════════════════════ -->

  <!--
    The caster is a passive support wheel — no motor, no joint limits.
    We model it as a sphere for two reasons:
    1. Spheres roll in any direction — just like a real caster swivels.
    2. Sphere contact physics in Gazebo is more stable than a cylinder caster.

    Joint type = fixed.
    A real caster swivels freely — but we model the swivel via physics,
    not a joint. Gazebo's contact model on a low-friction sphere
    naturally allows rotation in any direction. Fixed joint is correct here.
  -->
  <link name="caster_wheel">

    <visual>
      <geometry>
        <sphere radius="${caster_radius}"/>
      </geometry>
      <origin xyz="0 0 0" rpy="0 0 0"/>
      <material name="black"/>
    </visual>

    <collision>
      <geometry>
        <sphere radius="${caster_radius}"/>
      </geometry>
      <origin xyz="0 0 0" rpy="0 0 0"/>
    </collision>

    <!--
      sphere_inertia macro from inertia_macros.xacro.
      Small mass — caster is just a support ball, not a structural part.
    -->
    <xacro:sphere_inertia
      m="${caster_mass}"
      r="${caster_radius}"/>

  </link>

  <!--
    CASTER JOINT
    type="fixed" — no joint movement. Gazebo handles passive rolling
    through contact physics and the near-zero friction we set in gazebo.xacro.

    origin xyz:
      x = caster_x_offset = 0.15  (front of chassis)
      y = 0                        (centred left-right)
      z = caster_z_offset = -0.025 (caster centre is 2.5cm below base_link)
  -->
  <joint name="caster_wheel_joint" type="fixed">
    <parent link="base_link"/>
    <child  link="caster_wheel"/>
    <origin xyz="${caster_x_offset} 0 ${caster_z_offset}" rpy="0 0 0"/>
  </joint>

</robot>
